<?xml version="1.0"?>
<robot xmlns:sensor="http://playerstage.sourceforge.net/gazebo/xmlschema/#sensor"
       xmlns:controller="http://playerstage.sourceforge.net/gazebo/xmlschema/#controller"
       xmlns:interface="http://playerstage.sourceforge.net/gazebo/xmlschema/#interface"
       xmlns:xacro="http://playerstage.sourceforge.net/gazebo/xmlschema/#interface"
       name="vincent" >

  <material name="Blue">
    <color rgba="0.0 0.0 0.8 1.0"/>
  </material>
  <material name="Green">
    <color rgba="0.0 0.8 0.0 1.0"/>
  </material>
  <material name="Grey">
    <color rgba="0.7 0.7 0.7 1.0"/>
  </material>
  <material name="Grey2">
    <color rgba="0.9 0.9 0.9 1.0"/>
  </material>
  <material name="Red">
    <color rgba="0.8 0.0 0.0 1.0"/>
  </material>
  <material name="White">
    <color rgba="1.0 1.0 1.0 1.0"/>
  </material>
  <material name="Black">
    <color rgba="0.1 0.1 0.1 1.0"/>
  </material>
  <material name="LightGrey">
    <color rgba="0.6 0.6 0.6 1.0"/>
  </material>

  <link name="root_link"/>
  <link name="base_prismatic_dummy1"/>
  <link name="base_prismatic_dummy2"/>
  <link name="base_prismatic_dummy3"/>
  <link name="base_revolute_dummy1"/>
  <link name="base_revolute_dummy2"/>

  <joint name="base_prismatic_joint_x" type="prismatic">
    <axis xyz="1 0 0"/>
    <limit effort="10000" lower="-300.0" upper="300.0" velocity="0.6"/>
    <safety_controller k_position="100" k_velocity="2000000" soft_lower_limit="-300.0" soft_upper_limit="300.0"/>
    <calibration falling="0.00536"/>
    <dynamics damping="20000.0"/>
    <origin rpy="0 0 0" xyz="0 0 0.9619"/>
    <parent link="root_link"/>
    <child link="base_prismatic_dummy1"/>
  </joint>
  <joint name="base_prismatic_joint_y" type="prismatic">
    <axis xyz="0 1 0"/>
    <limit effort="10000" lower="-300.0" upper="300.0" velocity="0.6"/>
    <safety_controller k_position="100" k_velocity="2000000" soft_lower_limit="-300.0" soft_upper_limit="300.0"/>
    <calibration falling="0.00536"/>
    <dynamics damping="20000.0"/>
    <origin rpy="0 0 0" xyz="0 0 0"/>
    <parent link="base_prismatic_dummy1"/>
    <child link="base_prismatic_dummy2"/>
  </joint>
  <joint name="base_prismatic_joint_z" type="prismatic">
    <axis xyz="0 0 1"/>
    <limit effort="10000" lower="-10" upper="10" velocity="0.6"/>
    <safety_controller k_position="100" k_velocity="2000000" soft_lower_limit="-10" soft_upper_limit="10"/>
    <calibration falling="0.00536"/>
    <dynamics damping="20000.0"/>
    <origin rpy="0 0 0" xyz="0 0 0"/>
    <parent link="base_prismatic_dummy2"/>
    <child link="base_prismatic_dummy3"/>
  </joint>
  <joint name="base_revolute_joint_x" type="revolute">
    <axis xyz="1 0 0"/>
    <limit effort="15" lower="-1.57" upper="1.57" velocity="5"/>
    <origin rpy="0 0 0" xyz="0 0 0"/>
    <parent link="base_prismatic_dummy3"/>
    <child link="base_revolute_dummy1"/>
  </joint>
  <joint name="base_revolute_joint_y" type="revolute">
    <axis xyz="0 1 0"/>
    <limit effort="15" lower="-1.57" upper="1.57" velocity="5"/>
    <origin rpy="0 0 0" xyz="0 0 0"/>
    <parent link="base_revolute_dummy1"/>
    <child link="base_revolute_dummy2"/>
  </joint>
  <joint name="base_revolute_joint_z" type="revolute">
    <axis xyz="0 0 1"/>
    <limit effort="15" lower="-6.28" upper="6.28" velocity="5"/>
    <origin rpy="0 0 0" xyz="0 0 0"/>
    <parent link="base_revolute_dummy2"/>
    <child link="pelvis_link"/>
  </joint>  
  <link name="pelvis_link">
    <visual>
      <origin rpy="0 0 0" xyz="0 0 0"/>
      <geometry>
        <mesh filename="package://human_character_description/meshes/vincent/pelvis.dae"/>
      </geometry>
      <material name="Blue"/>
    </visual>
    <collision>
      <origin rpy="0 0 0" xyz="0 0 0"/>
      <geometry>
        <mesh filename="package://human_character_description/meshes/vincent/collision/pelvis_col.dae"/>
      </geometry>
    </collision>
    <inertial>
      <mass value="0"/>
      <inertia ixx="0.22" ixy="0.0" ixz="0.0" iyy="0.22" iyz="0.0" izz="0.23"/>
      <origin xyz="0 0 0"/>
    </inertial>
  </link>	  
  <joint name="torso_z_joint" type="revolute">
    <axis xyz="0 0 1"/>
    <limit effort="15" lower="-1.57" upper="1.57" velocity="5"/>
    <origin rpy="0 0 0" xyz="0.0 0.01576 0.09227"/>
    <parent link="pelvis_link"/>
    <child link="torso_z_link"/>
  </joint>
  <joint name="torso_y_joint" type="revolute">
    <axis xyz="0 1 0"/>
    <limit effort="15" lower="-1.57" upper="1.57" velocity="5"/>
    <origin rpy="0 0 0" xyz="0 0 0"/>
    <parent link="torso_z_link"/>
    <child link="torso_y_link"/>
  </joint>
  <joint name="torso_x_joint" type="revolute">
    <axis xyz="1 0 0"/>
    <limit effort="15" lower="-1.57" upper="0.5" velocity="5"/>
    <origin rpy="0 0 0" xyz="0 0 0"/>
    <parent link="torso_y_link"/>
    <child link="torso_x_link"/>
  </joint>  

  <link name="torso_z_link"/>
  <link name="torso_y_link"/>
  <link name="torso_x_link">
    <visual>
      <origin rpy="0 0 0" xyz="0 0 0"/>
      <geometry>
        <mesh filename="package://human_character_description/meshes/vincent/torso.dae"/>
      </geometry>
      <material name="Blue"/>
    </visual>
    <collision>
      <origin rpy="0 0 0" xyz="0 0 0"/>
      <geometry>
        <mesh filename="package://human_character_description/meshes/vincent/collision/torso_col.dae"/>
      </geometry>
    </collision>
    <inertial>
      <mass value="37.6936"/>
      <inertia ixx="1.308" ixy="0.0" ixz="0.0" iyy="1.308" iyz="0.0" izz="0.3119"/>
      <origin xyz="0 0 0.159042454"/>
    </inertial>
  </link>  
  
  <joint name="head_z_joint" type="revolute">
    <axis xyz="0 0 1"/>
    <limit effort="15" lower="-0.5" upper="0.5" velocity="5"/>
    <origin rpy="0 0 0" xyz="0.00002 -0.04885 0.48111"/>
    <parent link="torso_x_link"/>
    <child link="head_z_link"/>
  </joint>
  <joint name="head_y_joint" type="revolute">
    <axis xyz="0 1 0"/>
    <limit effort="15" lower="-0.5" upper="0.5" velocity="5"/>
    <origin rpy="0 0 0" xyz="0 0 0"/>
    <parent link="head_z_link"/>
    <child link="head_y_link"/>
  </joint>
  <joint name="head_x_joint" type="revolute">
    <axis xyz="1 0 0"/>
    <limit effort="15" lower="-0.5" upper="0.5" velocity="5"/>
    <origin rpy="0 0 0" xyz="0 0 0"/>
    <parent link="head_y_link"/>
    <child link="head_x_link"/>
  </joint>

  <link name="head_z_link"/>
  <link name="head_y_link"/>
  <link name="head_x_link">
    <visual>
      <origin rpy="0 0 0" xyz="0 0 0"/>
      <geometry>
        <mesh filename="package://human_character_description/meshes/vincent/head.dae"/>
      </geometry>
      <material name="Blue"/>
    </visual>
    <collision>
      <origin rpy="0 0 0" xyz="0 0 0"/>
      <geometry>
        <mesh filename="package://human_character_description/meshes/vincent/collision/head_col.dae"/>
      </geometry>
    </collision>
    <inertial>
      <mass value="5.4166"/>
      <inertia ixx="0.0248" ixy="0.0" ixz="0.0" iyy="0.0248" iyz="0.0" izz="0.0"/>
      <origin xyz="0.0 0.0 0.117409854"/>
    </inertial>
  </link>
  
  <joint name="head_endeffector_joint" type="fixed">
    <axis xyz="0 0 1"/>
    <limit effort="15" lower="-0.001" upper="0.001" velocity="5"/>
    <origin rpy="0 0 0" xyz="0 0.00981 0.21913"/>
    <parent link="head_x_link"/>
    <child link="head_endeffector_link"/>
  </joint>

  <link name="head_endeffector_link"/>

  <joint name="upper_left_leg_z_joint" type="revolute">
    <axis xyz="0 0 1"/>
    <limit effort="15" lower="-3.14" upper="3.14" velocity="5"/>
    <origin rpy="0 0 0" xyz="-0.09633 -0.00001 -0.03273"/>
    <parent link="pelvis_link"/>
    <child link="upper_left_leg_z_link"/>
  </joint>
  <joint name="upper_left_leg_y_joint" type="revolute">
    <axis xyz="0 1 0"/>
    <limit effort="15" lower="-3.14" upper="3.14" velocity="5"/>
    <origin rpy="0 0 0" xyz="0 0 0"/>
    <parent link="upper_left_leg_z_link"/>
    <child link="upper_left_leg_y_link"/>
  </joint>
  <joint name="upper_left_leg_x_joint" type="revolute">
    <axis xyz="1 0 0"/>
    <limit effort="15" lower="-3.14" upper="3.14" velocity="5"/>
    <origin rpy="0 0 0" xyz="0 0 0"/>
    <parent link="upper_left_leg_y_link"/>
    <child link="upper_left_leg_x_link"/>
  </joint>

  <link name="upper_left_leg_z_link"/>
  <link name="upper_left_leg_y_link"/>
  <link name="upper_left_leg_x_link">
    <visual>
      <origin rpy="0 0 0" xyz="0 0 0"/>
      <geometry>
        <mesh filename="package://human_character_description/meshes/vincent/l_upperleg.dae"/>
      </geometry>
      <material name="Blue"/>
    </visual>
    <collision>
      <origin rpy="0 0 0" xyz="0 0 0"/>
      <geometry>
        <mesh filename="package://human_character_description/meshes/vincent/collision/l_upperleg_col.dae"/>
      </geometry>
    </collision>
    <inertial>
      <mass value="7.33096"/>
      <inertia ixx="0.1502" ixy="0.0" ixz="0.0" iyy="0.1502" iyz="0.0" izz="0.0"/>
      <origin xyz="0.0 0.0 -0.18082513"/>
    </inertial>
  </link>

  <joint name="lower_left_leg_joint" type="revolute">
    <axis xyz="1 0 0"/>
    <limit effort="15" lower="-3.14" upper="0.1" velocity="5"/>
    <origin rpy="0 0 0" xyz="0 -0.00654 -0.41761"/>
    <parent link="upper_left_leg_x_link"/>
    <child link="lower_left_leg_link"/>
  </joint>

  <link name="lower_left_leg_link">
    <visual>
      <origin rpy="0 0 0" xyz="0 0 0"/>
      <geometry>
        <mesh filename="package://human_character_description/meshes/vincent/l_lowerleg.dae"/>
      </geometry>
      <material name="Blue"/>
    </visual>
    <collision>
      <origin rpy="0 0 0" xyz="0 0 0"/>
      <geometry>
        <mesh filename="package://human_character_description/meshes/vincent/collision/l_lowerleg_col.dae"/>
      </geometry>
    </collision>
    <inertial>
      <mass value="3.4503"/>
      <inertia ixx="0.0505" ixy="0.0" ixz="0.0" iyy="0.0505" iyz="0.0" izz="0.0"/>
      <origin xyz="0.0 0.0 -0.16954548"/>
    </inertial>
  </link>

  <joint name="left_foot_z_joint" type="revolute">
    <axis xyz="0 0 1"/>
    <limit effort="15" lower="-3.14" upper="3.14" velocity="5"/>
    <origin rpy="0 0 0" xyz="-0.00012 -0.01923 -0.39156"/>
    <parent link="lower_left_leg_link"/>
    <child link="left_foot_z_link"/>
  </joint>
  <joint name="left_foot_y_joint" type="revolute">
    <axis xyz="0 1 0"/>
    <limit effort="15" lower="-3.14" upper="3.14" velocity="5"/>
    <origin rpy="0 0 0" xyz="0 0 0"/>
    <parent link="left_foot_z_link"/>
    <child link="left_foot_y_link"/>
  </joint>
  <joint name="left_foot_x_joint" type="revolute">
    <axis xyz="1 0 0"/>
    <limit effort="15" lower="-3.14" upper="3.14" velocity="5"/>
    <origin rpy="0 0 0" xyz="0 0 0"/>
    <parent link="left_foot_y_link"/>
    <child link="left_foot_x_link"/>
  </joint>

  <link name="left_foot_z_link"/>
  <link name="left_foot_y_link"/>
  <link name="left_foot_x_link">
    <visual>
      <origin rpy="0 0 0" xyz="0 0 0"/>
      <geometry>
        <mesh filename="package://human_character_description/meshes/vincent/l_foot.dae"/>
      </geometry>
      <material name="Blue"/>
    </visual>
    <collision>
      <origin rpy="0 0 0" xyz="0 0 0"/>
      <geometry>
        <mesh filename="package://human_character_description/meshes/vincent/collision/l_foot_col.dae"/>
      </geometry>
    </collision>
    <inertial>
      <mass value="1.0759"/>
      <inertia ixx="0.0" ixy="0.0" ixz="0.0" iyy="0.0038" iyz="0.0" izz="0.0"/>
      <origin xyz="-0.00861 0.08296 -0.06"/>
    </inertial>
  </link>
	
	  
  <joint name="left_foot_endeffector_joint" type="revolute">
    <axis xyz="0 0 1"/>
    <limit effort="15" lower="0.0" upper="0.0" velocity="5"/>
    <origin rpy="0 0 0" xyz="0 0 -0.12"/>
    <parent link="left_foot_x_link"/>
    <child link="left_foot_endeffector_link"/>
  </joint>

  <link name="left_foot_endeffector_link"/>  

  <joint name="upper_right_leg_z_joint" type="revolute">
    <axis xyz="0 0 1"/>
    <limit effort="15" lower="-3.14" upper="3.14" velocity="5"/>
    <origin rpy="0 0 0" xyz="0.09635 -0.00001 -0.03273"/> 
    <parent link="pelvis_link"/>
    <child link="upper_right_leg_z_link"/>
  </joint>
  <joint name="upper_right_leg_y_joint" type="revolute">
    <axis xyz="0 1 0"/>
    <limit effort="15" lower="-3.14" upper="3.14" velocity="5"/>
    <origin rpy="0 0 0" xyz="0 0 0"/>
    <parent link="upper_right_leg_z_link"/>
    <child link="upper_right_leg_y_link"/>
  </joint>
  <joint name="upper_right_leg_x_joint" type="revolute">
    <axis xyz="1 0 0"/>
    <limit effort="15" lower="-3.14" upper="3.14" velocity="5"/>
    <origin rpy="0 0 0" xyz="0 0 0"/>
    <parent link="upper_right_leg_y_link"/>
    <child link="upper_right_leg_x_link"/>
  </joint>

  <link name="upper_right_leg_z_link"/>
  <link name="upper_right_leg_y_link"/>
  <link name="upper_right_leg_x_link">
    <visual>
      <origin rpy="0 0 0" xyz="0 0 0"/>
      <geometry>
        <mesh filename="package://human_character_description/meshes/vincent/r_upperleg.dae"/>
      </geometry>
      <material name="Blue"/>
    </visual>
    <collision>
      <origin rpy="0 0 0" xyz="0 0 0"/>
      <geometry>
        <mesh filename="package://human_character_description/meshes/vincent/collision/r_upperleg_col.dae"/>
      </geometry>
    </collision>
    <inertial>
      <mass value="7.33096"/>
      <inertia ixx="0.1502" ixy="0.0" ixz="0.0" iyy="0.1502" iyz="0.0" izz="0.0"/>
      <origin xyz="0.0 0.0 -0.18082513"/>
    </inertial>
  </link>

  <joint name="lower_right_leg_joint" type="revolute">
    <axis xyz="1 0 0"/>
    <limit effort="15" lower="-3.14" upper="0.1" velocity="5"/>
    <origin rpy="0 0 0" xyz="0 -0.00654 -0.41761"/>
    <parent link="upper_right_leg_x_link"/>
    <child link="lower_right_leg_link"/>
  </joint>

  <link name="lower_right_leg_link">
    <visual>
      <origin rpy="0 0 0" xyz="0 0 0"/>
      <geometry>
        <mesh filename="package://human_character_description/meshes/vincent/r_lowerleg.dae"/>
      </geometry>
      <material name="Blue"/>
    </visual>
    <collision>
      <origin rpy="0 0 0" xyz="0 0 0"/>
      <geometry>
        <mesh filename="package://human_character_description/meshes/vincent/collision/r_lowerleg_col.dae"/>
      </geometry>
    </collision>
    <inertial>
      <mass value="3.4503"/>
      <inertia ixx="0.0505" ixy="0.0" ixz="0.0" iyy="0.0505" iyz="0.0" izz="0.0"/>
      <origin xyz="0.0 0.0 -0.16954548"/>
    </inertial>
  </link>

  <joint name="right_foot_z_joint" type="revolute">
    <axis xyz="0 0 1"/>
    <limit effort="15" lower="-3.14" upper="3.14" velocity="5"/>
    <origin rpy="0 0 0" xyz="-0.00013 -0.01923 -0.39156"/>
    <parent link="lower_right_leg_link"/>
    <child link="right_foot_z_link"/>
  </joint>
  <joint name="right_foot_y_joint" type="revolute">
    <axis xyz="0 1 0"/>
    <limit effort="15" lower="-3.14" upper="3.14" velocity="5"/>
    <origin rpy="0 0 0" xyz="0 0 0"/>
    <parent link="right_foot_z_link"/>
    <child link="right_foot_y_link"/>
  </joint>
  <joint name="right_foot_x_joint" type="revolute">
    <axis xyz="1 0 0"/>
    <limit effort="15" lower="-3.14" upper="3.14" velocity="5"/>
    <origin rpy="0 0 0" xyz="0 0 0"/>
    <parent link="right_foot_y_link"/>
    <child link="right_foot_x_link"/>
  </joint>

  <link name="right_foot_z_link"/>
  <link name="right_foot_y_link"/>
  <link name="right_foot_x_link">
    <visual>
      <origin rpy="0 0 0" xyz="0 0 0"/>
      <geometry>
        <mesh filename="package://human_character_description/meshes/vincent/r_foot.dae"/>
      </geometry>
      <material name="Blue"/>
    </visual>
    <collision>
      <origin rpy="0 0 0" xyz="0 0 0"/>
      <geometry>
        <mesh filename="package://human_character_description/meshes/vincent/collision/r_foot_col.dae"/>
      </geometry>
    </collision>
    <inertial>
      <mass value="1.0759"/>
      <inertia ixx="0.0" ixy="0.0" ixz="0.0" iyy="0.0038" iyz="0.0" izz="0.0"/>
      <origin xyz="0.00861 0.08296 -0.06"/>
    </inertial>
  </link>
  	  
  <joint name="right_foot_endeffector_joint" type="revolute">
    <axis xyz="0 0 1"/>
    <limit effort="15" lower="0.0" upper="0.0" velocity="5"/>
    <origin rpy="0 0 0" xyz="0 0 -0.12"/>
    <parent link="right_foot_x_link"/>
    <child link="right_foot_endeffector_link"/>
  </joint>

  <link name="right_foot_endeffector_link"/>

  <joint name="upper_left_specula_joint" type="revolute">
    <axis xyz="0 0 1"/>
    <limit effort="15" lower="-0.5" upper="0.5" velocity="5"/>
    <origin rpy="0 0 0" xyz="-0.06142 -0.05251 0.4008"/>
    <parent link="torso_x_link"/>
    <child link="upper_left_arm_specula_link"/>
  </joint>
  
  <link name="upper_left_arm_specula_link">
      <visual>
      <origin rpy="0 0 0" xyz="0 0 0"/>
      <geometry>
        <mesh filename="package://human_character_description/meshes/vincent/l_speculum.dae"/>
      </geometry>
      <material name="Blue"/>
    </visual>
    <collision>
      <origin rpy="0 0 0" xyz="0 0 0"/>
      <geometry>
        <mesh filename="package://human_character_description/meshes/vincent/collision/l_speculum_col.dae"/>
      </geometry>
    </collision>
    <inertial>
      <mass value="0.0"/>
      <inertia ixx="0.01" ixy="0.0" ixz="0.0" iyy="0.01" iyz="0.0" izz="0.01"/>
      <origin xyz="0.0 0.0 0.0"/>
    </inertial>
  </link>

  <joint name="upper_left_arm_x_joint" type="revolute">
    <axis xyz="1 0 0"/>
    <limit effort="15" lower="-6.28" upper="6.28" velocity="5"/>
    <origin rpy="0 0 0" xyz="-0.12319 0.0363053 -0.01113"/>
    <parent link="upper_left_arm_specula_link"/>
    <child link="upper_left_arm_x_link"/>
  </joint>
  <joint name="upper_left_arm_y_joint" type="revolute">
    <axis xyz="0 1 0"/>
    <limit effort="15" lower="-6.28" upper="6.28" velocity="5"/>
    <origin rpy="0 0 0" xyz="0 0 0"/>
    <parent link="upper_left_arm_x_link"/>
    <child link="upper_left_arm_y_link"/>
  </joint>
  <joint name="upper_left_arm_z_joint" type="revolute">
    <axis xyz="0 0 1"/>
    <limit effort="15" lower="-6.28" upper="6.28" velocity="5"/>
    <origin rpy="0 0 0" xyz="0 0 0"/>
    <parent link="upper_left_arm_y_link"/>
    <child link="upper_left_arm_z_link"/>
  </joint>

  <link name="upper_left_arm_x_link"/>
  <link name="upper_left_arm_y_link"/>
  <link name="upper_left_arm_z_link">
    <visual>
      <origin rpy="0 0 0" xyz="0 0 0"/>
      <geometry>
        <mesh filename="package://human_character_description/meshes/vincent/l_upperarm.dae"/>
      </geometry>
      <material name="Blue"/>
    </visual>
    <collision>
      <origin rpy="0 0 0" xyz="0 0 0"/>
      <geometry>
        <mesh filename="package://human_character_description/meshes/vincent/collision/l_upperarm_col.dae"/>
      </geometry>
    </collision>
    <inertial>
      <mass value="2.0034"/>
      <inertia ixx="0.0" ixy="0.0" ixz="0.0" iyy="0.0213" iyz="0.0" izz="0.0213"/>
      <origin xyz="-0.12071532 0.0 0.0"/>
    </inertial>
  </link>

  <joint name="lower_left_arm_joint" type="revolute">
    <axis xyz="0 0 1"/>
    <limit effort="15" lower="-2.5" upper="0.1" velocity="5"/>
    <origin rpy="0 0 0" xyz="-0.27687 -0.02 0.0"/>
    <parent link="upper_left_arm_z_link"/>
    <child link="lower_left_arm_link"/>
  </joint>

  <link name="lower_left_arm_link">
    <visual>
      <origin rpy="0 0 0" xyz="0 0 0"/>
      <geometry>
        <mesh filename="package://human_character_description/meshes/vincent/l_forearm.dae"/>
      </geometry>
      <material name="Blue"/>
    </visual>
    <collision>
      <origin rpy="0 0 0" xyz="0 0 0"/>
      <geometry>
        <mesh filename="package://human_character_description/meshes/vincent/collision/l_forearm_col.dae"/>
      </geometry>
    </collision>
    <inertial>
      <mass value="1.1872"/>
      <inertia ixx="0.0" ixy="0.0" ixz="0.0" iyy="0.076" iyz="0.0" izz="0.076"/>
      <origin xyz="-0.1198582 0.0 0.0"/>
    </inertial>
  </link>

  <joint name="left_hand_z_joint" type="revolute">
    <axis xyz="0 0 1"/>
    <limit effort="15" lower="-6.28" upper="6.28" velocity="5"/>
    <origin rpy="0 0 0" xyz="-0.27874 0.0 0.0"/>
    <parent link="lower_left_arm_link"/>
    <child link="left_hand_z_link"/>
  </joint>
  <joint name="left_hand_y_joint" type="revolute">
    <axis xyz="0 1 0"/>
    <limit effort="15" lower="-6.28" upper="6.28" velocity="5"/>
    <origin rpy="0 0 0" xyz="0 0 0"/>
    <parent link="left_hand_z_link"/>
    <child link="left_hand_y_link"/>
  </joint>
  <joint name="left_hand_x_joint" type="revolute">
    <axis xyz="1 0 0"/>
    <limit effort="15" lower="-6.28" upper="6.28" velocity="5"/>
    <origin rpy="0 0 0" xyz="0 0 0"/>
    <parent link="left_hand_y_link"/>
    <child link="left_hand_x_link"/>
  </joint>

  <link name="left_hand_z_link"/>
  <link name="left_hand_y_link"/>
  <link name="left_hand_x_link">
    <visual>
      <origin rpy="0 0 0" xyz="0 0 0"/>
      <geometry>
        <mesh filename="package://human_character_description/meshes/vincent/l_hand.dae"/>
      </geometry>
      <material name="Blue"/>
    </visual>
    <collision>
      <origin rpy="0 0 0" xyz="0 0 0"/>
      <geometry>
        <mesh filename="package://human_character_description/meshes/vincent/collision/l_hand_col.dae"/>
      </geometry>
    </collision>
    <inertial>
      <mass value="0.48972"/>
      <inertia ixx="0.0" ixy="0.0" ixz="0.0" iyy="0.0005" iyz="0.0" izz="0.0005"/>
      <origin xyz="-0.04806494 0.0 0.0"/>
    </inertial>
  </link>

  <joint name="left_hand_endeffector_joint" type="revolute">
    <axis xyz="0 0 1"/>
    <limit effort="15" lower="-0.001" upper="0.001" velocity="5"/>
    <origin rpy="0 0 0" xyz="-0.015 0.0 -0.01"/>
        <parent link="left_hand_x_link"/>
    <child link="left_hand_endeffector_link"/>
  </joint>

  <link name="left_hand_endeffector_link"/>
  
  <joint name="upper_right_specula_joint" type="revolute">
    <axis xyz="0 0 1"/>
    <limit effort="15" lower="-0.5" upper="0.5" velocity="5"/>
    <origin rpy="0 0 0" xyz="0.06142 -0.05251 0.4008"/>
    <parent link="torso_x_link"/>
    <child link="upper_right_arm_specula_link"/>
  </joint>
    
  <link name="upper_right_arm_specula_link">
      <visual>
      <origin rpy="0 0 0" xyz="0 0 0"/>
      <geometry>
        <mesh filename="package://human_character_description/meshes/vincent/r_speculum.dae"/>
      </geometry>
      <material name="Blue"/>
    </visual>
    <collision>
      <origin rpy="0 0 0" xyz="0 0 0"/>
      <geometry>
        <mesh filename="package://human_character_description/meshes/vincent/collision/r_speculum_col.dae"/>
      </geometry>
    </collision>
    <inertial>
      <mass value="0.0"/>
      <inertia ixx="0.01" ixy="0.0" ixz="0.0" iyy="0.01" iyz="0.0" izz="0.01"/>
      <origin xyz="0.0 0.0 0.0"/>
    </inertial>
  </link>

  <joint name="upper_right_arm_x_joint" type="revolute">
    <axis xyz="1 0 0"/>
    <limit effort="15" lower="-6.28" upper="6.28" velocity="5"/>
    <origin rpy="0 0 0" xyz="0.12323 0.0363053 -0.01113"/>
    <parent link="upper_right_arm_specula_link"/>
    <child link="upper_right_arm_x_link"/>
  </joint>
  <joint name="upper_right_arm_y_joint" type="revolute">
    <axis xyz="0 1 0"/>
    <limit effort="15" lower="-6.28" upper="6.28" velocity="5"/>
    <origin rpy="0 0 0" xyz="0 0 0"/>
    <parent link="upper_right_arm_x_link"/>
    <child link="upper_right_arm_y_link"/>
  </joint>
  <joint name="upper_right_arm_z_joint" type="revolute">
    <axis xyz="0 0 1"/>
    <limit effort="15" lower="-6.28" upper="6.28" velocity="5"/>
    <origin rpy="0 0 0" xyz="0 0 0"/>
    <parent link="upper_right_arm_y_link"/>
    <child link="upper_right_arm_z_link"/>
  </joint>

  <link name="upper_right_arm_x_link"/>
  <link name="upper_right_arm_y_link"/>
  <link name="upper_right_arm_z_link">
    <visual>
      <origin rpy="0 0 0" xyz="0 0 0"/>
      <geometry>
        <mesh filename="package://human_character_description/meshes/vincent/r_upperarm.dae"/>
      </geometry>
      <material name="Blue"/>
    </visual>
    <collision>
      <origin rpy="0 0 0" xyz="0 0 0"/>
      <geometry>
        <mesh filename="package://human_character_description/meshes/vincent/collision/r_upperarm_col.dae"/>
      </geometry>
    </collision>
    <inertial>
      <mass value="2.0034"/>
      <inertia ixx="0.0" ixy="0.0" ixz="0.0" iyy="0.0213" iyz="0.0" izz="0.0213"/>
      <origin xyz="0.12071532 0.0 0.0"/>
    </inertial>
  </link>


  <joint name="lower_right_arm_joint" type="revolute">
    <axis xyz="0 0 1"/>
    <limit effort="15" lower="-0.1" upper="2.5" velocity="5"/>
    <origin rpy="0 0 0" xyz="0.27687 -0.02 0.0"/>
    <parent link="upper_right_arm_z_link"/>
    <child link="lower_right_arm_link"/>
  </joint>

  <link name="lower_right_arm_link">
    <visual>
      <origin rpy="0 0 0" xyz="0 0 0"/>
      <geometry>
        <mesh filename="package://human_character_description/meshes/vincent/r_forearm.dae"/>
      </geometry>
      <material name="Blue"/>
    </visual>
    <collision>
      <origin rpy="0 0 0" xyz="0 0 0"/>
      <geometry>
        <mesh filename="package://human_character_description/meshes/vincent/collision/r_forearm_col.dae"/>
      </geometry>
    </collision>
    <inertial>
      <mass value="1.1872"/>
      <inertia ixx="0.0" ixy="0.0" ixz="0.0" iyy="0.076" iyz="0.0" izz="0.076"/>
      <origin xyz="0.1198582 0.0 0.0"/>
    </inertial>
  </link>

  <joint name="right_hand_z_joint" type="revolute">
    <axis xyz="0 0 1"/>
    <limit effort="15" lower="-6.28" upper="6.28" velocity="5"/>
    <origin rpy="0 0 0" xyz="0.27874 0.0 0.0"/>
    <parent link="lower_right_arm_link"/>
    <child link="right_hand_z_link"/>
  </joint>
  <joint name="right_hand_y_joint" type="revolute">
    <axis xyz="0 1 0"/>
    <limit effort="15" lower="-6.28" upper="6.28" velocity="5"/>
    <origin rpy="0 0 0" xyz="0 0 0"/>
    <parent link="right_hand_z_link"/>
    <child link="right_hand_y_link"/>
  </joint>
  <joint name="right_hand_x_joint" type="revolute">
    <axis xyz="1 0 0"/>
    <limit effort="15" lower="-6.28" upper="6.28" velocity="5"/>
    <origin rpy="0 0 0" xyz="0 0 0"/>
    <parent link="right_hand_y_link"/>
    <child link="right_hand_x_link"/>
  </joint>

  <link name="right_hand_z_link"/>
  <link name="right_hand_y_link"/>
  <link name="right_hand_x_link">
    <visual>
      <origin rpy="0 0 0" xyz="0 0 0"/>
      <geometry>
        <mesh filename="package://human_character_description/meshes/vincent/r_hand.dae"/>
      </geometry>
      <material name="Blue"/>
    </visual>
    <collision>
      <origin rpy="0 0 0" xyz="0 0 0"/>
      <geometry>
        <mesh filename="package://human_character_description/meshes/vincent/collision/r_hand_col.dae"/>
      </geometry>
    </collision>
    <inertial>
      <mass value="0.48972"/>
      <inertia ixx="0.0" ixy="0.0" ixz="0.0" iyy="0.0005" iyz="0.0" izz="0.0005"/>
      <origin xyz="0.04806494 0.0 0.0"/>
    </inertial>
  </link>

  <joint name="right_hand_endeffector_joint" type="revolute">
    <axis xyz="0 0 1"/>
    <limit effort="15" lower="-0.001" upper="0.001" velocity="5"/>
    <origin rpy="0 0 0" xyz="0.015 0.0 -0.01"/>
    <parent link="right_hand_x_link"/>
    <child link="right_hand_endeffector_link"/>
  </joint>

  <link name="right_hand_endeffector_link"/>

  <link name="left_foot_cp_1_link"/>
  <link name="left_foot_cp_2_link"/>
  <link name="left_foot_cp_3_link"/>
  <link name="left_foot_cp_4_link"/>

  <joint name="left_foot_cp_1_joint" type="revolute">
    <axis xyz="0 0 1"/>
    <limit effort="15" lower="0" upper="0" velocity="5"/>
    <origin rpy="0 0 0" xyz="0.04 0.22 0.0"/>
    <parent link="left_foot_endeffector_link"/>
    <child link="left_foot_cp_1_link"/>
  </joint>
  <joint name="left_foot_cp_2_joint" type="revolute">
    <axis xyz="0 0 1"/>
    <limit effort="15" lower="0" upper="0" velocity="5"/>
    <origin rpy="0 0 0" xyz="-0.06 0.22 0.0"/>
    <parent link="left_foot_endeffector_link"/>
    <child link="left_foot_cp_2_link"/>
  </joint>
  <joint name="left_foot_cp_3_joint" type="revolute">
    <axis xyz="0 0 1"/>
    <limit effort="15" lower="0" upper="0" velocity="5"/>
    <origin rpy="0 0 0" xyz="-0.06 -0.02 0.0"/>
    <parent link="left_foot_endeffector_link"/>
    <child link="left_foot_cp_3_link"/>
  </joint>
  <joint name="left_foot_cp_4_joint" type="revolute">
    <axis xyz="0 0 1"/>
    <limit effort="15" lower="0" upper="0" velocity="5"/>
    <origin rpy="0 0 0" xyz="0.03 -0.02 0.0"/>
    <parent link="left_foot_endeffector_link"/>
    <child link="left_foot_cp_4_link"/>
  </joint>

  <link name="right_foot_cp_1_link"/>
  <link name="right_foot_cp_2_link"/>
  <link name="right_foot_cp_3_link"/>
  <link name="right_foot_cp_4_link"/>

  <joint name="right_foot_cp_1_joint" type="revolute">
    <axis xyz="0 0 1"/>
    <limit effort="15" lower="0" upper="0" velocity="5"/>
    <origin rpy="0 0 0" xyz="-0.04 0.22 0.0"/>
    <parent link="right_foot_endeffector_link"/>
    <child link="right_foot_cp_1_link"/>
  </joint>
  <joint name="right_foot_cp_2_joint" type="revolute">
    <axis xyz="0 0 1"/>
    <limit effort="15" lower="0" upper="0" velocity="5"/>
    <origin rpy="0 0 0" xyz="0.06 0.22 0.0"/>
    <parent link="right_foot_endeffector_link"/>
    <child link="right_foot_cp_2_link"/>
  </joint>
  <joint name="right_foot_cp_3_joint" type="revolute">
    <axis xyz="0 0 1"/>
    <limit effort="15" lower="0" upper="0" velocity="5"/>
    <origin rpy="0 0 0" xyz="0.06 -0.02 0.0"/>
    <parent link="right_foot_endeffector_link"/>
    <child link="right_foot_cp_3_link"/>
  </joint>
  <joint name="right_foot_cp_4_joint" type="revolute">
    <axis xyz="0 0 1"/>
    <limit effort="15" lower="0" upper="0" velocity="5"/>
    <origin rpy="0 0 0" xyz="-0.03 -0.02 0.0"/>
    <parent link="right_foot_endeffector_link"/>
    <child link="right_foot_cp_4_link"/>
  </joint>

  <link name="left_hand_cp_1_link"/>
  <link name="left_hand_cp_2_link"/>
  <link name="left_hand_cp_3_link"/>
  <link name="left_hand_cp_4_link"/>

  <joint name="left_hand_cp_1_joint" type="revolute">
    <axis xyz="0 0 1"/>
    <limit effort="15" lower="0" upper="0" velocity="5"/>
    <origin rpy="0 0 0" xyz="-0.08 0.025 0"/>
    <parent link="left_hand_endeffector_link"/>
    <child link="left_hand_cp_1_link"/>
  </joint>
  <joint name="left_hand_cp_2_joint" type="revolute">
    <axis xyz="0 0 1"/>
    <limit effort="15" lower="0" upper="0" velocity="5"/>
    <origin rpy="0 0 0" xyz="-0.08 -0.02 0"/>
    <parent link="left_hand_endeffector_link"/>
    <child link="left_hand_cp_2_link"/>
  </joint>
  <joint name="left_hand_cp_3_joint" type="revolute">
    <axis xyz="0 0 1"/>
    <limit effort="15" lower="0" upper="0" velocity="5"/>
    <origin rpy="0 0 0" xyz="0.0 -0.02 0"/>
    <parent link="left_hand_endeffector_link"/>
    <child link="left_hand_cp_3_link"/>
  </joint>
  <joint name="left_hand_cp_4_joint" type="revolute">
    <axis xyz="0 0 1"/>
    <limit effort="15" lower="0" upper="0" velocity="5"/>
    <origin rpy="0 0 0" xyz="0.0 0.025 0"/>
    <parent link="left_hand_endeffector_link"/>
    <child link="left_hand_cp_4_link"/>
  </joint>

  <link name="right_hand_cp_1_link"/>
  <link name="right_hand_cp_2_link"/>
  <link name="right_hand_cp_3_link"/>
  <link name="right_hand_cp_4_link"/>

  <joint name="right_hand_cp_1_joint" type="revolute">
    <axis xyz="0 0 1"/>
    <limit effort="15" lower="0" upper="0" velocity="5"/>
    <origin rpy="0 0 0" xyz="0.08 0.025 0"/>
    <parent link="right_hand_endeffector_link"/>
    <child link="right_hand_cp_1_link"/>
  </joint>
  <joint name="right_hand_cp_2_joint" type="revolute">
    <axis xyz="0 0 1"/>
    <limit effort="15" lower="0" upper="0" velocity="5"/>
    <origin rpy="0 0 0" xyz="0.08 -0.02 0"/>
    <parent link="right_hand_endeffector_link"/>
    <child link="right_hand_cp_2_link"/>
  </joint>
  <joint name="right_hand_cp_3_joint" type="revolute">
    <axis xyz="0 0 1"/>
    <limit effort="15" lower="0" upper="0" velocity="5"/>
    <origin rpy="0 0 0" xyz="0.0 -0.02 0"/>
    <parent link="right_hand_endeffector_link"/>
    <child link="right_hand_cp_3_link"/>
  </joint>
  <joint name="right_hand_cp_4_joint" type="revolute">
    <axis xyz="0 0 1"/>
    <limit effort="15" lower="0" upper="0" velocity="5"/>
    <origin rpy="0 0 0" xyz="0.0 0.025 0"/>
    <parent link="right_hand_endeffector_link"/>
    <child link="right_hand_cp_4_link"/>
  </joint>

</robot>

